<?xml version="1.0" encoding="utf-8"?>
<!-- This URDF was automatically created by SolidWorks to URDF Exporter! Originally created by Stephen Brawner (brawner@gmail.com) 
     Commit Version: 1.6.0-4-g7f85cfe  Build Version: 1.6.7995.38578
     For more information, please see http://wiki.ros.org/sw_urdf_exporter -->
<robot
  name="urdf">
  <link
    name="base_link">
    <inertial>
      <origin
        xyz="0.057859 0.001501 -0.041397"
        rpy="0 0 0" />
      <mass
        value="2.5758" />
      <inertia
        ixx="0.0092346"
        ixy="6.9354E-14"
        ixz="-6.0236E-06"
        iyy="0.0022342"
        iyz="-1.6085E-08"
        izz="0.0081961" />
    </inertial>
    <visual>
      <origin
        xyz="0 0 0"
        rpy="0 -1.5708 0" />
      <geometry>
        <mesh
          filename="../meshes/base_link.STL" />
      </geometry>
      <material
        name="">
        <color
          rgba="0 0.7 1 1" />
      </material>
    </visual>
    <collision>
      <origin
        xyz="0 0 0"
        rpy="0 0 0" />
      <geometry>
        <mesh
          filename="../meshes/base_link.STL" />
      </geometry>
    </collision>
  </link>
  <link
    name="right_hip_yaw">
    <inertial>
      <origin
        xyz="2.9122E-06 0.054374 -0.010038"
        rpy="0 0 0" />
      <mass
        value="0.59683" />
      <inertia
        ixx="0.00034663"
        ixy="1.1374E-08"
        ixz="4.6368E-10"
        iyy="0.0005471"
        iyz="-2.4987E-05"
        izz="0.0003578" />
    </inertial>
    <visual>
      <origin
        xyz="0 0 0"
        rpy="0 0 0" />
      <geometry>
        <mesh
          filename="../meshes/right_hip_yaw.STL" />
      </geometry>
      <material
        name="">
        <color
          rgba="0.1 0.5 0.9 1" />
      </material>
    </visual>
    <collision>
      <origin
        xyz="0 0 0"
        rpy="0 0 0" />
      <geometry>
        <mesh
          filename="../meshes/right_hip_yaw.STL" />
      </geometry>
    </collision>
  </link>
  <joint
    name="right_hip_yaw_joint"
    type="revolute">
    <origin
      xyz="0 0.0815 0"
      rpy="0 -1.57 0" />
    <parent
      link="base_link" />
    <child
      link="right_hip_yaw" />
    <axis
      xyz="0 0 1" />
    <limit
      lower="-2"
      upper="2"
      effort="100"
      velocity="50" />
  </joint>
  <link
    name="right_hip_pitch">
    <inertial>
      <origin
        xyz="-0.11354 -0.0015123 -1.6386E-05"
        rpy="0 0 0" />
      <mass
        value="1.6182" />
      <inertia
        ixx="0.0011021"
        ixy="-5.7248E-06"
        ixz="-1.9836E-08"
        iyy="0.0021829"
        iyz="1.6084E-08"
        izz="0.0013784" />
    </inertial>
    <visual>
      <origin
        xyz="0 0 0"
        rpy="0 0 0" />
      <geometry>
        <mesh
          filename="../meshes/right_hip_pitch.STL" />
      </geometry>
      <material
        name="">
        <color
          rgba="0 0.7 1 1" />
      </material>
    </visual>
    <collision>
      <origin
        xyz="0 0 0"
        rpy="0 0 0" />
      <geometry>
        <mesh
          filename="../meshes/right_hip_pitch.STL" />
      </geometry>
    </collision>
  </link>
  <joint
    name="right_hip_pitch_joint"
    type="revolute">
    <origin
      xyz="0 0 0"
      rpy="0 0 0" />
    <parent
      link="right_hip_yaw" />
    <child
      link="right_hip_pitch" />
    <axis
      xyz="0 1 0" />
    <limit
      lower="-2"
      upper="2"
      effort="100"
      velocity="50" />
  </joint>
  <link
    name="right_knee_pitch">
    <inertial>
      <origin
        xyz="-0.1367 1.3619E-06 1.9168E-08"
        rpy="0 0 0" />
      <mass
        value="0.24651" />
      <inertia
        ixx="5.0068E-05"
        ixy="1.6384E-11"
        ixz="1.6187E-10"
        iyy="0.00053"
        iyz="3.0738E-11"
        izz="0.00052582" />
    </inertial>
    <visual>
      <origin
        xyz="0 0 0"
        rpy="0 0 0" />
      <geometry>
        <mesh
          filename="../meshes/right_knee_pitch.STL" />
      </geometry>
      <material
        name="">
        <color
          rgba="0.1 0.5 0.9 1" />
      </material>
    </visual>
    <collision>
      <origin
        xyz="0 0 0"
        rpy="0 0 0" />
      <geometry>
        <mesh
          filename="../meshes/right_knee_pitch.STL" />
      </geometry>
    </collision>
  </link>
  <joint
    name="right_knee_pitch_joint"
    type="revolute">
    <origin
      xyz="-0.3 0 0"
      rpy="0 0 0" />
    <parent
      link="right_hip_pitch" />
    <child
      link="right_knee_pitch" />
    <axis
      xyz="0 1 0" />
    <limit
      lower="-2"
      upper="2"
      effort="100"
      velocity="50" />
  </joint>
  <link
    name="right_ankle_pitch">
    <inertial>
      <origin
        xyz="9.9075E-11 -5.5733E-14 4.2181E-11"
        rpy="0 0 0" />
      <mass
        value="0.019465" />
      <inertia
        ixx="9.1427E-06"
        ixy="-5.0568E-22"
        ixz="2.5241E-17"
        iyy="8.9831E-06"
        iyz="-4.2502E-20"
        izz="8.8017E-07" />
    </inertial>
    <visual>
      <origin
        xyz="0 0 0"
        rpy="0 0 0" />
      <geometry>
        <mesh
          filename="../meshes/right_ankle_pitch.STL" />
      </geometry>
      <material
        name="">
        <color
          rgba="0 0.7 1 1" />
      </material>
    </visual>
    <collision>
      <origin
        xyz="0 0 0"
        rpy="0 0 0" />
      <geometry>
        <mesh
          filename="../meshes/right_ankle_pitch.STL" />
      </geometry>
    </collision>
  </link>
  <joint
    name="right_ankle_pitch_joint"
    type="revolute">
    <origin
      xyz="-0.311 0 0"
      rpy="0 0 0" />
    <parent
      link="right_knee_pitch" />
    <child
      link="right_ankle_pitch" />
    <axis
      xyz="0 1 0" />
    <limit
      lower="-2"
      upper="2"
      effort="100"
      velocity="50" />
  </joint>
  <link
    name="right_ankle_roll">
    <inertial>
      <origin
        xyz="-0.031487 -5.8287E-14 0.02571"
        rpy="0 0 0" />
      <mass
        value="0.27177" />
      <inertia
        ixx="0.00153"
        ixy="9.4808E-19"
        ixz="3.9706E-15"
        iyy="0.0013044"
        iyz="-5.6928E-18"
        izz="0.00023021" />
    </inertial>
    <visual>
      <origin
        xyz="0 0 0"
        rpy="0 0 0" />
      <geometry>
        <mesh
          filename="../meshes/right_ankle_roll.STL" />
      </geometry>
      <material
        name="">
        <color
          rgba="0 0 0.7 1" />
      </material>
    </visual>
    <collision>
      <origin
        xyz="0 0 0"
        rpy="0 0 0" />
      <geometry>
        <mesh
          filename="../meshes/right_ankle_roll.STL" />
      </geometry>
    </collision>
  </link>
  <joint
    name="right_ankle_roll_joint"
    type="revolute">
    <origin
      xyz="0 0 0"
      rpy="0 0 0" />
    <parent
      link="right_ankle_pitch" />
    <child
      link="right_ankle_roll" />
    <axis
      xyz="0 0 1" />
    <limit
      lower="-2"
      upper="2"
      effort="100"
      velocity="50" />
  </joint>
  <link
    name="left_hip_yaw">
    <inertial>
      <origin
        xyz="-8.4201E-06 -0.054374 -0.010011"
        rpy="0 0 0" />
      <mass
        value="0.59683" />
      <inertia
        ixx="0.00034666"
        ixy="-1.6084E-08"
        ixz="-1.9812E-08"
        iyy="0.0005471"
        iyz="2.4998E-05"
        izz="0.00035778" />
    </inertial>
    <visual>
      <origin
        xyz="0 0 0"
        rpy="0 -1.5708 0" />
      <geometry>
        <mesh
          filename="../meshes/left_hip_yaw.STL" />
      </geometry>
      <material
        name="">
        <color
          rgba="0.1 0.5 0.9 1" />
      </material>
    </visual>
    <collision>
      <origin
        xyz="0 0 0"
        rpy="0 0 0" />
      <geometry>
        <mesh
          filename="../meshes/left_hip_yaw.STL" />
      </geometry>
    </collision>
  </link>
  <joint
    name="left_hip_yaw_joint"
    type="revolute">
    <origin
      xyz="0 -0.0785 0"
      rpy="0 0 0" />
    <parent
      link="base_link" />
    <child
      link="left_hip_yaw" />
    <axis
      xyz="1 0 0" />
    <limit
      lower="-2"
      upper="2"
      effort="100"
      velocity="50" />
  </joint>
  <link
    name="left_hip_pitch">
    <inertial>
      <origin
        xyz="-0.11317 -0.0014447 1.9E-05"
        rpy="0 0 0" />
      <mass
        value="1.6236" />
      <inertia
        ixx="0.0011021"
        ixy="5.7134E-06"
        ixz="-5.0662E-10"
        iyy="0.0021829"
        iyz="1.1372E-08"
        izz="0.0013785" />
    </inertial>
    <visual>
      <origin
        xyz="0 0 0"
        rpy="0 0 0" />
      <geometry>
        <mesh
          filename="../meshes/left_hip_pitch.STL" />
      </geometry>
      <material
        name="">
        <color
          rgba="0 0.7 1 1" />
      </material>
    </visual>
    <collision>
      <origin
        xyz="0 0 0"
        rpy="0 0 0" />
      <geometry>
        <mesh
          filename="../meshes/left_hip_pitch.STL" />
      </geometry>
    </collision>
  </link>
  <joint
    name="left_hip_pitch_joint"
    type="revolute">
    <origin
      xyz="0 0 0"
      rpy="0 -1.5708 0" />
    <parent
      link="left_hip_yaw" />
    <child
      link="left_hip_pitch" />
    <axis
      xyz="0 1 0" />
    <limit
      lower="-2"
      upper="2"
      effort="100"
      velocity="50" />
  </joint>
  <link
    name="left_knee_pitch">
    <inertial>
      <origin
        xyz="-0.1367 -0.0029986 2.6673E-08"
        rpy="0 0 0" />
      <mass
        value="0.24651" />
      <inertia
        ixx="5.0068E-05"
        ixy="1.6384E-11"
        ixz="1.6188E-10"
        iyy="0.00053"
        iyz="3.0738E-11"
        izz="0.00052582" />
    </inertial>
    <visual>
      <origin
        xyz="0 0 0"
        rpy="0 0 0" />
      <geometry>
        <mesh
          filename="../meshes/left_knee_pitch.STL" />
      </geometry>
      <material
        name="">
        <color
          rgba="0.1 0.5 0.9 1" />
      </material>
    </visual>
    <collision>
      <origin
        xyz="0 0 0"
        rpy="0 0 0" />
      <geometry>
        <mesh
          filename="../meshes/left_knee_pitch.STL" />
      </geometry>
    </collision>
  </link>
  <joint
    name="left_knee_pitch_joint"
    type="revolute">
    <origin
      xyz="-0.3 0 0"
      rpy="0 0 0" />
    <parent
      link="left_hip_pitch" />
    <child
      link="left_knee_pitch" />
    <axis
      xyz="0 1 0" />
    <limit
      lower="-2"
      upper="2"
      effort="100"
      velocity="50" />
  </joint>
  <link
    name="left_ankle_pitch">
    <inertial>
      <origin
        xyz="-3.4062E-13 -4.2577E-14 -1.3267E-13"
        rpy="0 0 0" />
      <mass
        value="0.019465" />
      <inertia
        ixx="9.1427E-06"
        ixy="1.2896E-20"
        ixz="-2.5657E-17"
        iyy="8.9831E-06"
        iyz="3.7893E-21"
        izz="8.8017E-07" />
    </inertial>
    <visual>
      <origin
        xyz="0 0 0"
        rpy="0 0 0" />
      <geometry>
        <mesh
          filename="../meshes/left_ankle_pitch.STL" />
      </geometry>
      <material
        name="">
        <color
          rgba="0 0.7 1 1" />
      </material>
    </visual>
    <collision>
      <origin
        xyz="0 0 0"
        rpy="0 0 0" />
      <geometry>
        <mesh
          filename="../meshes/left_ankle_pitch.STL" />
      </geometry>
    </collision>
  </link>
  <joint
    name="left_ankle_pitch_joint"
    type="revolute">
    <origin
      xyz="-0.311 -0.003 0"
      rpy="0 0 0" />
    <parent
      link="left_knee_pitch" />
    <child
      link="left_ankle_pitch" />
    <axis
      xyz="0 1 0" />
    <limit
      lower="-2"
      upper="2"
      effort="100"
      velocity="50" />
  </joint>
  <link
    name="left_ankle_roll">
    <inertial>
      <origin
        xyz="-0.031487 -4.5131E-14 0.02571"
        rpy="0 0 0" />
      <mass
        value="0.27177" />
      <inertia
        ixx="0.00153"
        ixy="1.8286E-17"
        ixz="-4.0381E-15"
        iyy="0.0013044"
        iyz="-1.1095E-18"
        izz="0.00023021" />
    </inertial>
    <visual>
      <origin
        xyz="0 0 0"
        rpy="0 0 0" />
      <geometry>
        <mesh
          filename="../meshes/left_ankle_roll.STL" />
      </geometry>
      <material
        name="">
        <color
          rgba="0 0 0.7 1" />
      </material>
    </visual>
    <collision>
      <origin
        xyz="0 0 0"
        rpy="0 0 0" />
      <geometry>
        <mesh
          filename="../meshes/left_ankle_roll.STL" />
      </geometry>
    </collision>
  </link>
  <joint
    name="left_ankle_roll_joint"
    type="revolute">
    <origin
      xyz="0 0 0"
      rpy="0 0 0" />
    <parent
      link="left_ankle_pitch" />
    <child
      link="left_ankle_roll" />
    <axis
      xyz="0 0 1" />
    <limit
      lower="-2"
      upper="2"
      effort="100"
      velocity="50" />
  </joint>
</robot>
